Workbook

Sheet Read Me
B2: SATE System Test — linked workbook
B3: Every table is joined to the others. Nothing here is a typed-in number.
B6: HOW THE SHEETS CONNECT
B7: Requirements ↔ Test Cases | C7: Many-to-many. A test case lists its requirements in "Requirement IDs"; a requirement lists its cases in "Linked Test Cases". Both directions are written as real values, so they are correct in any spreadsheet application.
B8: Traceability | C8: The join table itself — one row per (requirement, test case) pair, 181 rows. This is the sheet to filter when you need "everything covering RQ-11" or "every requirement this case touches". The test case status column pulls live from Test Cases.
B9: Defect Log → Test Cases | C9: The Test Case ID column is a dropdown restricted to real IDs, so a defect cannot reference a case that does not exist. Title, Category, Priority and Requirement IDs then fill in by lookup — you type the ID and nothing else.
B10: Test Cases → Defect Log | C10: The "Defects" column counts matching rows in the Defect Log, so a case shows its open defects without you cross-referencing by hand.
B11: Summary → Test Cases | C11: Every figure is a formula over the Test Cases sheet. Change one Status and the whole summary moves. The original workbook had these as constants, which went stale the moment anyone ran a test.
B12: Lists | C12: One controlled vocabulary drives every dropdown in the workbook. Edit it there, not in the sheets that use it.
B14: WHAT IS A FORMULA AND WHAT IS DATA
B15: Data (safe, permanent) | C15: Which requirement covers which case. These relationships do not change during a test run, so they are stored as values and cannot break.
B16: Formulas (live) | C16: Anything derived from Status — pass counts, coverage, blockers. Status is the one column that changes while you are testing, so these must recalculate.
B18: HOW TO RUN IT
B19: 1. Settle the blocked requirements | C19: Ten requirements are still "Needs confirmation" or "Partially defined". A case depending on one cannot pass or fail — mark it Blocked and record what you saw. The "Blocked By" column on Test Cases flags them for you.
B20: 2. Filter to P0 and work down | C20: 65 of 88 cases are P0. A failed P0 is a release blocker by default.
B21: 3. Fill Status, then the rest | C21: Status is the only column the summary depends on. Actual Result, Evidence and Defect ID are for the record.
B22: 4. Raise defects in the Defect Log | C22: Pick the Test Case ID from the dropdown; the rest fills itself in.
B24: BEFORE YOU TOUCH A DEVICE
B25: Check the system is up | C25: Run "sate infra" in hwtest/ — it probes auth, database, device-api including the v15 verify route, Storage, the Cloudflare worker, the AI queue and device heartbeat. Half of a failed test run is a service that was already down.
B26: Use a unique session label | C26: Say it aloud at the start and end of every recording. It is the only way to prove a transcript belongs to the audio you think it does.
B28: COMPANION DOCUMENT
B29: doc/13-system-test.md | C29: The same 88 cases written as step-by-step instructions, each with a server-side note naming the actual table, route and constant to check. The "Server-Side Check" column here is a condensed version of those notes.

Sheet Summary
B2: SATE system test — live summary
B3: Every figure below is a formula over the Test Cases sheet. Change a Status and this moves.
B5: EXECUTION
B6: Metric | C6: Total | D6: P0 | E6: P1 | F6: P2
B7: Total cases | C7: =COUNTA('Test Cases'!$I$2:$I$89) | D7: =COUNTIF('Test Cases'!$I$2:$I$89,"P0") | E7: =COUNTIF('Test Cases'!$I$2:$I$89,"P1") | F7: =COUNTIF('Test Cases'!$I$2:$I$89,"P2")
B8: Not Run | C8: =COUNTIF('Test Cases'!$X$2:$X$89,"Not Run") | D8: =COUNTIFS('Test Cases'!$X$2:$X$89,"Not Run",'Test Cases'!$I$2:$I$89,"P0") | E8: =COUNTIFS('Test Cases'!$X$2:$X$89,"Not Run",'Test Cases'!$I$2:$I$89,"P1") | F8: =COUNTIFS('Test Cases'!$X$2:$X$89,"Not Run",'Test Cases'!$I$2:$I$89,"P2")
B9: Pass | C9: =COUNTIF('Test Cases'!$X$2:$X$89,"Pass") | D9: =COUNTIFS('Test Cases'!$X$2:$X$89,"Pass",'Test Cases'!$I$2:$I$89,"P0") | E9: =COUNTIFS('Test Cases'!$X$2:$X$89,"Pass",'Test Cases'!$I$2:$I$89,"P1") | F9: =COUNTIFS('Test Cases'!$X$2:$X$89,"Pass",'Test Cases'!$I$2:$I$89,"P2")
B10: Fail | C10: =COUNTIF('Test Cases'!$X$2:$X$89,"Fail") | D10: =COUNTIFS('Test Cases'!$X$2:$X$89,"Fail",'Test Cases'!$I$2:$I$89,"P0") | E10: =COUNTIFS('Test Cases'!$X$2:$X$89,"Fail",'Test Cases'!$I$2:$I$89,"P1") | F10: =COUNTIFS('Test Cases'!$X$2:$X$89,"Fail",'Test Cases'!$I$2:$I$89,"P2")
B11: Blocked | C11: =COUNTIF('Test Cases'!$X$2:$X$89,"Blocked") | D11: =COUNTIFS('Test Cases'!$X$2:$X$89,"Blocked",'Test Cases'!$I$2:$I$89,"P0") | E11: =COUNTIFS('Test Cases'!$X$2:$X$89,"Blocked",'Test Cases'!$I$2:$I$89,"P1") | F11: =COUNTIFS('Test Cases'!$X$2:$X$89,"Blocked",'Test Cases'!$I$2:$I$89,"P2")
B12: Skipped | C12: =COUNTIF('Test Cases'!$X$2:$X$89,"Skipped") | D12: =COUNTIFS('Test Cases'!$X$2:$X$89,"Skipped",'Test Cases'!$I$2:$I$89,"P0") | E12: =COUNTIFS('Test Cases'!$X$2:$X$89,"Skipped",'Test Cases'!$I$2:$I$89,"P1") | F12: =COUNTIFS('Test Cases'!$X$2:$X$89,"Skipped",'Test Cases'!$I$2:$I$89,"P2")
B13: Executed | C13: =C9+C10+C11
B14: Progress | C14: =IF(C7=0,0,(C9+C10+C11)/C7)
B16: RELEASE GATE
B17: P0 failures | C17: =COUNTIFS('Test Cases'!$X$2:$X$89,"Fail",'Test Cases'!$I$2:$I$89,"P0") | D17: =IF(C17=0,"CLEAR","BLOCKED")
B18: Open defects | C18: =COUNTIFS('Defect Log'!$I$2:$I$201,"Open")
B19: Release blockers logged | C19: =COUNTIF('Defect Log'!$H$2:$H$201,"Release Blocker")
B20: Cases blocked by undecided requirements | C20: =COUNTIF('Test Cases'!$M$2:$M$89,"?*")
B23: SCOPE OF THIS RUN
B24: Mobile app and pendant are OUT of scope. Recorder, backend, web app and PDF are in.
B25: Scope | C25: Cases | D25: P0 | E25: Pass | F25: Fail | G25: Blocked | H25: Not Run
B26: In scope | C26: =COUNTIF('Test Cases'!$B$2:$B$89,$B26) | D26: =COUNTIFS('Test Cases'!$B$2:$B$89,$B26,'Test Cases'!$I$2:$I$89,"P0") | E26: =COUNTIFS('Test Cases'!$B$2:$B$89,$B26,'Test Cases'!$X$2:$X$89,"Pass") | F26: =COUNTIFS('Test Cases'!$B$2:$B$89,$B26,'Test Cases'!$X$2:$X$89,"Fail") | G26: =COUNTIFS('Test Cases'!$B$2:$B$89,$B26,'Test Cases'!$X$2:$X$89,"Blocked") | H26: =COUNTIFS('Test Cases'!$B$2:$B$89,$B26,'Test Cases'!$X$2:$X$89,"Not Run")
B27: In scope (reduced) | C27: =COUNTIF('Test Cases'!$B$2:$B$89,$B27) | D27: =COUNTIFS('Test Cases'!$B$2:$B$89,$B27,'Test Cases'!$I$2:$I$89,"P0") | E27: =COUNTIFS('Test Cases'!$B$2:$B$89,$B27,'Test Cases'!$X$2:$X$89,"Pass") | F27: =COUNTIFS('Test Cases'!$B$2:$B$89,$B27,'Test Cases'!$X$2:$X$89,"Fail") | G27: =COUNTIFS('Test Cases'!$B$2:$B$89,$B27,'Test Cases'!$X$2:$X$89,"Blocked") | H27: =COUNTIFS('Test Cases'!$B$2:$B$89,$B27,'Test Cases'!$X$2:$X$89,"Not Run")
B28: Deferred - mobile app | C28: =COUNTIF('Test Cases'!$B$2:$B$89,$B28) | D28: =COUNTIFS('Test Cases'!$B$2:$B$89,$B28,'Test Cases'!$I$2:$I$89,"P0") | E28: =COUNTIFS('Test Cases'!$B$2:$B$89,$B28,'Test Cases'!$X$2:$X$89,"Pass") | F28: =COUNTIFS('Test Cases'!$B$2:$B$89,$B28,'Test Cases'!$X$2:$X$89,"Fail") | G28: =COUNTIFS('Test Cases'!$B$2:$B$89,$B28,'Test Cases'!$X$2:$X$89,"Blocked") | H28: =COUNTIFS('Test Cases'!$B$2:$B$89,$B28,'Test Cases'!$X$2:$X$89,"Not Run")
B29: Deferred - pendant / BLE | C29: =COUNTIF('Test Cases'!$B$2:$B$89,$B29) | D29: =COUNTIFS('Test Cases'!$B$2:$B$89,$B29,'Test Cases'!$I$2:$I$89,"P0") | E29: =COUNTIFS('Test Cases'!$B$2:$B$89,$B29,'Test Cases'!$X$2:$X$89,"Pass") | F29: =COUNTIFS('Test Cases'!$B$2:$B$89,$B29,'Test Cases'!$X$2:$X$89,"Fail") | G29: =COUNTIFS('Test Cases'!$B$2:$B$89,$B29,'Test Cases'!$X$2:$X$89,"Blocked") | H29: =COUNTIFS('Test Cases'!$B$2:$B$89,$B29,'Test Cases'!$X$2:$X$89,"Not Run")
B30: RUNNING THIS PASS | C30: =C26+C27 | D30: =D26+D27
B33: WHO RUNS WHAT
B34: Test Side | C34: Cases | D34: P0 | E34: Pass | F34: Fail | G34: Blocked | H34: Not Run
B35: End User | C35: =COUNTIF('Test Cases'!$D$2:$D$89,$B35) | D35: =COUNTIFS('Test Cases'!$D$2:$D$89,$B35,'Test Cases'!$I$2:$I$89,"P0") | E35: =COUNTIFS('Test Cases'!$D$2:$D$89,$B35,'Test Cases'!$X$2:$X$89,"Pass") | F35: =COUNTIFS('Test Cases'!$D$2:$D$89,$B35,'Test Cases'!$X$2:$X$89,"Fail") | G35: =COUNTIFS('Test Cases'!$D$2:$D$89,$B35,'Test Cases'!$X$2:$X$89,"Blocked") | H35: =COUNTIFS('Test Cases'!$D$2:$D$89,$B35,'Test Cases'!$X$2:$X$89,"Not Run") | I35: Tester alone — recorder, phone, browser. No backend access needed.
B36: Both | C36: =COUNTIF('Test Cases'!$D$2:$D$89,$B36) | D36: =COUNTIFS('Test Cases'!$D$2:$D$89,$B36,'Test Cases'!$I$2:$I$89,"P0") | E36: =COUNTIFS('Test Cases'!$D$2:$D$89,$B36,'Test Cases'!$X$2:$X$89,"Pass") | F36: =COUNTIFS('Test Cases'!$D$2:$D$89,$B36,'Test Cases'!$X$2:$X$89,"Fail") | G36: =COUNTIFS('Test Cases'!$D$2:$D$89,$B36,'Test Cases'!$X$2:$X$89,"Blocked") | H36: =COUNTIFS('Test Cases'!$D$2:$D$89,$B36,'Test Cases'!$X$2:$X$89,"Not Run") | I36: User performs it; pass/fail needs a server check. Plan for two people.
B37: Server Side | C37: =COUNTIF('Test Cases'!$D$2:$D$89,$B37) | D37: =COUNTIFS('Test Cases'!$D$2:$D$89,$B37,'Test Cases'!$I$2:$I$89,"P0") | E37: =COUNTIFS('Test Cases'!$D$2:$D$89,$B37,'Test Cases'!$X$2:$X$89,"Pass") | F37: =COUNTIFS('Test Cases'!$D$2:$D$89,$B37,'Test Cases'!$X$2:$X$89,"Fail") | G37: =COUNTIFS('Test Cases'!$D$2:$D$89,$B37,'Test Cases'!$X$2:$X$89,"Blocked") | H37: =COUNTIFS('Test Cases'!$D$2:$D$89,$B37,'Test Cases'!$X$2:$X$89,"Not Run") | I37: Cannot be judged from the UI. Fault injection and queue inspection.
B40: BY CATEGORY
B41: Category | C41: Cases | D41: P0 | E41: Pass | F41: Fail | G41: Blocked | H41: Not Run
B42: BLE and Device Connectivity | C42: =COUNTIF('Test Cases'!$G$2:$G$89,$B42) | D42: =COUNTIFS('Test Cases'!$G$2:$G$89,$B42,'Test Cases'!$I$2:$I$89,"P0") | E42: =COUNTIFS('Test Cases'!$G$2:$G$89,$B42,'Test Cases'!$X$2:$X$89,"Pass") | F42: =COUNTIFS('Test Cases'!$G$2:$G$89,$B42,'Test Cases'!$X$2:$X$89,"Fail") | G42: =COUNTIFS('Test Cases'!$G$2:$G$89,$B42,'Test Cases'!$X$2:$X$89,"Blocked") | H42: =COUNTIFS('Test Cases'!$G$2:$G$89,$B42,'Test Cases'!$X$2:$X$89,"Not Run")
B43: Backend, Retry, and AI Processing | C43: =COUNTIF('Test Cases'!$G$2:$G$89,$B43) | D43: =COUNTIFS('Test Cases'!$G$2:$G$89,$B43,'Test Cases'!$I$2:$I$89,"P0") | E43: =COUNTIFS('Test Cases'!$G$2:$G$89,$B43,'Test Cases'!$X$2:$X$89,"Pass") | F43: =COUNTIFS('Test Cases'!$G$2:$G$89,$B43,'Test Cases'!$X$2:$X$89,"Fail") | G43: =COUNTIFS('Test Cases'!$G$2:$G$89,$B43,'Test Cases'!$X$2:$X$89,"Blocked") | H43: =COUNTIFS('Test Cases'!$G$2:$G$89,$B43,'Test Cases'!$X$2:$X$89,"Not Run")
B44: Compatibility and Deployment | C44: =COUNTIF('Test Cases'!$G$2:$G$89,$B44) | D44: =COUNTIFS('Test Cases'!$G$2:$G$89,$B44,'Test Cases'!$I$2:$I$89,"P0") | E44: =COUNTIFS('Test Cases'!$G$2:$G$89,$B44,'Test Cases'!$X$2:$X$89,"Pass") | F44: =COUNTIFS('Test Cases'!$G$2:$G$89,$B44,'Test Cases'!$X$2:$X$89,"Fail") | G44: =COUNTIFS('Test Cases'!$G$2:$G$89,$B44,'Test Cases'!$X$2:$X$89,"Blocked") | H44: =COUNTIFS('Test Cases'!$G$2:$G$89,$B44,'Test Cases'!$X$2:$X$89,"Not Run")
B45: End-to-End Recording and Sync | C45: =COUNTIF('Test Cases'!$G$2:$G$89,$B45) | D45: =COUNTIFS('Test Cases'!$G$2:$G$89,$B45,'Test Cases'!$I$2:$I$89,"P0") | E45: =COUNTIFS('Test Cases'!$G$2:$G$89,$B45,'Test Cases'!$X$2:$X$89,"Pass") | F45: =COUNTIFS('Test Cases'!$G$2:$G$89,$B45,'Test Cases'!$X$2:$X$89,"Fail") | G45: =COUNTIFS('Test Cases'!$G$2:$G$89,$B45,'Test Cases'!$X$2:$X$89,"Blocked") | H45: =COUNTIFS('Test Cases'!$G$2:$G$89,$B45,'Test Cases'!$X$2:$X$89,"Not Run")
B46: Long Session and Performance | C46: =COUNTIF('Test Cases'!$G$2:$G$89,$B46) | D46: =COUNTIFS('Test Cases'!$G$2:$G$89,$B46,'Test Cases'!$I$2:$I$89,"P0") | E46: =COUNTIFS('Test Cases'!$G$2:$G$89,$B46,'Test Cases'!$X$2:$X$89,"Pass") | F46: =COUNTIFS('Test Cases'!$G$2:$G$89,$B46,'Test Cases'!$X$2:$X$89,"Fail") | G46: =COUNTIFS('Test Cases'!$G$2:$G$89,$B46,'Test Cases'!$X$2:$X$89,"Blocked") | H46: =COUNTIFS('Test Cases'!$G$2:$G$89,$B46,'Test Cases'!$X$2:$X$89,"Not Run")
B47: Mobile App Lifecycle and Authentication | C47: =COUNTIF('Test Cases'!$G$2:$G$89,$B47) | D47: =COUNTIFS('Test Cases'!$G$2:$G$89,$B47,'Test Cases'!$I$2:$I$89,"P0") | E47: =COUNTIFS('Test Cases'!$G$2:$G$89,$B47,'Test Cases'!$X$2:$X$89,"Pass") | F47: =COUNTIFS('Test Cases'!$G$2:$G$89,$B47,'Test Cases'!$X$2:$X$89,"Fail") | G47: =COUNTIFS('Test Cases'!$G$2:$G$89,$B47,'Test Cases'!$X$2:$X$89,"Blocked") | H47: =COUNTIFS('Test Cases'!$G$2:$G$89,$B47,'Test Cases'!$X$2:$X$89,"Not Run")
B48: Network, Offline, and Upload Recovery | C48: =COUNTIF('Test Cases'!$G$2:$G$89,$B48) | D48: =COUNTIFS('Test Cases'!$G$2:$G$89,$B48,'Test Cases'!$I$2:$I$89,"P0") | E48: =COUNTIFS('Test Cases'!$G$2:$G$89,$B48,'Test Cases'!$X$2:$X$89,"Pass") | F48: =COUNTIFS('Test Cases'!$G$2:$G$89,$B48,'Test Cases'!$X$2:$X$89,"Fail") | G48: =COUNTIFS('Test Cases'!$G$2:$G$89,$B48,'Test Cases'!$X$2:$X$89,"Blocked") | H48: =COUNTIFS('Test Cases'!$G$2:$G$89,$B48,'Test Cases'!$X$2:$X$89,"Not Run")
B49: PDF Export | C49: =COUNTIF('Test Cases'!$G$2:$G$89,$B49) | D49: =COUNTIFS('Test Cases'!$G$2:$G$89,$B49,'Test Cases'!$I$2:$I$89,"P0") | E49: =COUNTIFS('Test Cases'!$G$2:$G$89,$B49,'Test Cases'!$X$2:$X$89,"Pass") | F49: =COUNTIFS('Test Cases'!$G$2:$G$89,$B49,'Test Cases'!$X$2:$X$89,"Fail") | G49: =COUNTIFS('Test Cases'!$G$2:$G$89,$B49,'Test Cases'!$X$2:$X$89,"Blocked") | H49: =COUNTIFS('Test Cases'!$G$2:$G$89,$B49,'Test Cases'!$X$2:$X$89,"Not Run")
...

Sheet Lists
A1: Status | B1: Priority | C1: Test Side | D1: Severity | E1: Defect Status | F1: Category | G1: Test Type | H1: Requirement Status | I1: Scope
A2: Not Run | B2: P0 | C2: End User | D2: Release Blocker | E2: Open | F2: BLE and Device Connectivity | G2: Architecture / Idempotency | H2: Required | I2: In scope
A3: Pass | B3: P1 | C3: Server Side | D3: Critical | E3: In Progress | F3: Backend, Retry, and AI Processing | G3: Backward Compatibility | H3: Needs confirmation | I3: In scope (reduced)
A4: Fail | B4: P2 | C4: Both | D4: Major | E4: Fixed | F4: Compatibility and Deployment | G4: Boundary / Functional | H4: Partially defined | I4: Deferred - mobile app
A5: Blocked | D5: Minor | E5: Verified | F5: End-to-End Recording and Sync | G5: Boundary / Performance | I5: Deferred - pendant / BLE
A6: Skipped | D6: Cosmetic | E6: Reopened | F6: Long Session and Performance | G6: Compatibility
E7: Won't Fix | F7: Mobile App Lifecycle and Authentication | G7: Compatibility / Data Integrity
F8: Network, Offline, and Upload Recovery | G8: Compatibility / Layout
F9: PDF Export | G9: Compatibility / Performance
F10: Queue, Batch, and Concurrency | G10: Compatibility / Reliability
F11: Recorder Interruption and Local Persistence | G11: Concurrency / Functional
F12: Security, Privacy, and Data Isolation | G12: Concurrency / Idempotency
F13: Web Transcript Review | G13: Concurrency / Recovery
G14: Concurrency / State Machine
G15: Consistency / Recovery
G16: Data Integrity
G17: Data Integrity / Cache
G18: Data Integrity / Functional
G19: Functional
G20: Functional / Batch
G21: Functional / Compatibility
G22: Functional / Data Integrity
G23: Functional / End-to-End
G24: Functional / Security
G25: Idempotency / Integration
... G72: Timeout / Retry

Sheet Test Cases
A1: TC ID | B1: Scope | C1: Scope Note | D1: Test Side | E1: Run By | F1: Access Needed | G1: Category | H1: Test Case Title | I1: Priority | J1: Test Type | K1: Requirement IDs | L1: Req Count | M1: Blocked By | N1: Components | O1: Objective | P1: Preconditions | Q1: Test Data / Environment | R1: Test Steps | S1: Expected Device / App / Web Result | T1: Expected Backend / Data Result | U1: Server-Side Check | V1: Data Integrity / Validation | W1: Pass Criteria | X1: Status | Y1: Actual Result | Z1: Defects | AA1: Defect ID | AB1: Evidence / Notes | AC1: Executed By | AD1: Executed On
A2: SATE-E2E-001 | B2: In scope | D2: Both | E2: Tester + Engineer | F2: Recorder · phone · browser + Supabase read access | G2: End-to-End Recording and Sync | H2: Standard online recording, upload, processing, review, and PDF export | I2: P0 | J2: Functional / End-to-End | K2: RQ-01, RQ-02, RQ-03, RQ-04, RQ-16, RQ-20 | L2: 6 | M2: RQ-20 | N2: SATE Recorder; Wi-Fi; Supabase; Edge Functions; Cloudflare; AI service; Web App; PDF service | O2: Verify the complete production workflow for a normal session. | P2: Test user is active; recorder is assigned to the user; stable Internet is available; backend services are healthy; no existing test session uses the planned test label. | Q2: 5-minute normal speech recording; stable Wi-Fi; supported browser. | R2: 1. Start a new recording. 2. Speak the unique session label at the beginning and end. 3. Stop and save the recording. 4. Wait for upload and processing to complete. 5. Open the session in the Web App. 6. Review transcript and annotations. 7. Export the SATE report as PDF. | S2: Recorder shows clear Recording, Saved, Uploading, Processing, and Completed states. The Web App shows the correct session, audio, transcript, annotations, and report controls. PDF opens successfully. | T2: Exactly one session record and one valid audio object are created. Status transitions are valid and terminal state is Completed. AI result is attached to the same session. No duplicate processing job is created. | U2: Watch one row move through the state machine and stop: select id, status, attempts, processed, recording_id, bytes, storage_path, process_error from sate_device_sessions where device_serial = '<serial>' order by created_at desc limit 5; Status must go queued → processing → done and settle. recording_id must be non-null and resolve to exactly one recordings row. Confirm the storage object really exists — a row alone is not proof (the 413 bug once left ghost rows with no object). Then confirm the audio the recorder freed matches: GET /api/sessions/verify?... must answer stored:true for that session number and byte count. sate pipeline shows this live. | V2: Confirm session ID, user ID, device ID, timestamps, duration, audio beginning/end markers, transcript-session match, valid annotation JSON, and PDF-session match. | W2: All steps complete without manual recovery; no data loss, duplication, mis-association, or unhandled error occurs. | X2: Not Run | Z2: =COUNTIF('Defect Log'!$C$2:$C$500,$A2)
A3: SATE-E2E-002 | B3: In scope | D3: Both | E3: Tester + Engineer | F3: Recorder · phone · browser + Supabase read access | G3: End-to-End Recording and Sync | H3: Very short recording near the minimum supported duration | I3: P1 | J3: Boundary / Functional | K3: RQ-01, RQ-07, RQ-14 | L3: 3 | M3: RQ-07 | N3: SATE Recorder; Supabase; AI service; Web App | O3: Verify expected handling of a valid recording near the minimum duration. | P3: Minimum supported duration is documented or a provisional threshold is agreed for testing. | Q3: 10-15 second recording containing one clearly spoken sentence. | R3: 1. Start recording. 2. Record for the minimum supported duration. 3. Stop and sync. 4. Open the result in the Web App. 5. Attempt PDF export if the session completes. | S3: The recorder either accepts the session or shows a documented minimum-duration message. The Web App does not display an unexplained blank result. | T3: If accepted, one complete session is processed. If rejected, no orphan audio, session, or processing job remains. | U3: A take under MIN_AUDIO_SEC (env, default **0.4 s**) never reaches the AI at all — the container finalizes it no_text up front, because the AI service answers HTTP 500 on a near-empty WAV and a 5xx reads as transient, which used to retry-loop into a stuck error (hit real on session 35). So a 10–15 s take is well above that floor and must transcribe normally. There is no other minimum enforced server-side — RQ-07 is still unsettled, so record what actually happens rather than asserting a threshold. | V3: Check actual duration, session status, transcript presence, and absence of orphan records. | W3: Behavior matches the documented minimum-duration requirement and leaves the system in a consistent state. | X3: Not Run | Z3: =COUNTIF('Defect Log'!$C$2:$C$500,$A3)
A4: SATE-E2E-003 | B4: In scope | D4: Both | E4: Tester + Engineer | F4: Recorder · phone · browser + Supabase read access | G4: End-to-End Recording and Sync | H4: Silent or near-silent recording | I4: P1 | J4: Negative / Functional | K4: RQ-14, RQ-20 | L4: 2 | M4: RQ-20 | N4: SATE Recorder; AI service; Web App | O4: Verify that absence of speech is distinguished from pipeline failure. | P4: Backend services are healthy. | Q4: 2-minute recording with room tone and no intentional speech. | R4: 1. Record two minutes of silence or near-silence. 2. Stop and sync. 3. Wait for processing. 4. Open the session in the Web App. 5. Review status, transcript, and annotations. | S4: The session displays a clear outcome such as No Detectable Speech, Low Confidence, or an empty transcript with explanation. It must not remain indefinitely in Processing. | T4: AI response is stored as a valid result or a defined non-speech outcome. Processing status reaches a defined terminal state. | U4: Silence is a *result*, not a failure. cf-processor calls finalize({no_text:true}), the edge marks the session done, and **no recordings row is created**. Verify select status, no_text, recording_id from sate_device_sessions where id='<id>' gives done / true / null. A session sitting in processing here is the real bug — check the container logs before blaming the AI. | V4: Verify audio is playable and complete; transcript is not copied from another session; result JSON is valid. | W4: The system distinguishes valid silent audio from upload/processing failure and provides an actionable status. | X4: Not Run | Z4: =COUNTIF('Defect Log'!$C$2:$C$500,$A4)
A5: SATE-E2E-004 | B5: In scope | D5: Both | E5: Tester + Engineer | F5: Recorder · phone · browser + Supabase read access | G5: End-to-End Recording and Sync | H5: Noisy recording with multiple speakers and interruptions | I5: P1 | J5: Robustness / Functional | K5: RQ-14, RQ-20 | L5: 2 | M5: RQ-20 | N5: SATE Recorder; AI service; Web App | O5: Verify that difficult audio degrades recognition quality gracefully without breaking the pipeline. | P5: Normal end-to-end environment is available. | Q5: 5-minute recording with background noise, two speakers, pauses, overlapping speech, and brief interruptions. | R5: 1. Record the prepared noisy scenario. 2. Stop and sync. 3. Review transcript, speaker-related output if supported, annotations, warnings, and PDF. | S5: The session completes or shows a defined low-quality warning. The UI remains responsive and does not mislabel the result as an upload failure. | T5: One valid audio object and one result set are stored. Partial/low-confidence fields follow the documented schema. | U5: Nothing special server-side: one sate_device_sessions row, one recordings row. Check recordings.transcript parses as JSON and recordings.analysis has the computed metrics (ntw, ndw, mluw, mlum, errorCounts). Diarization quality is not a pass criterion — pipeline integrity is. | V5: Check that output belongs to this audio, JSON fields are parseable, and no unrelated transcript appears. | W5: The session reaches a defined terminal state with no crash, malformed data, or cross-session contamination. | X5: Not Run | Z5: =COUNTIF('Defect Log'!$C$2:$C$500,$A5)
A6: SATE-E2E-005 | B6: In scope | D6: Both | E6: Tester + Engineer | F6: Recorder · phone · browser + Supabase read access | G6: End-to-End Recording and Sync | H6: Session metadata, timestamp, time-zone, and device association | I6: P0 | J6: Data Integrity | K6: RQ-01, RQ-02, RQ-19 | L6: 3 | N6: SATE Recorder; Supabase; Web App; PDF service | O6: Verify that metadata remains correct across recorder, backend, Web App, and exported report. | P6: Recorder and phone clocks are set correctly; test account and device assignment are known. | Q6: One 2-minute session created near a known clock time; record local time zone. | R6: 1. Note user, recorder ID, local start time, and end time. 2. Record and sync a session. 3. Compare metadata in device UI, database, Web App, and PDF. 4. Refresh and reopen the session. | S6: User name/ID, device, date, time, duration, and session label are consistent and displayed in the intended time zone. | T6: Canonical timestamps are stored consistently; display conversion is correct; device association does not change after refresh. | U6: Canonical timestamps are stored UTC (ISO-8601). Compare sate_device_sessions.created_at, recordings.created_at, and what the web app renders; a mismatch is a display-layer bug, not a storage one. Device association is sate_devices.id → sate_device_sessions.user_id; it must not change on refresh. | V6: Compare session ID, user ID, device ID, start/end timestamps, time zone, and calculated duration across all components. | W6: No incorrect user/device association, unexplained time shift, or material duration discrepancy is present. | X6: Not Run | Z6: =COUNTIF('Defect Log'!$C$2:$C$500,$A6)
A7: SATE-E2E-006 | B7: In scope (reduced) | C7: Repeat Stop / Save / Upload on the recorder only. Skip the app's Submit control. | D7: Both | E7: Tester + Engineer | F7: Recorder · phone · browser + Supabase read access | G7: End-to-End Recording and Sync | H7: Repeated Stop, Save, Upload, or Submit actions | I7: P0 | J7: Reliability / Idempotency | K7: RQ-03, RQ-21 | L7: 2 | M7: RQ-21 | N7: SATE Recorder; Mobile App; Supabase; Edge Functions | O7: Verify that rapid repeated user actions do not create duplicate sessions or jobs. | P7: Normal recording is in progress; tester can tap controls rapidly. | Q7: 2-minute recording; stable network. | R7: 1. End the recording. 2. Rapidly tap Stop/Save several times. 3. If an Upload or Retry control appears, tap it repeatedly. 4. Wait for completion. 5. Inspect session list and backend records. | S7: Controls become disabled or requests are safely deduplicated. The user sees only one session. | T7: Exactly one canonical session, one final audio object, and one final result set exist. Duplicate requests use the same idempotency key or are rejected safely. | U7: This is the idempotency case. storeSessionRecord probes for an existing row by **(user, serial, patient, session_number, bytes) + objectExists** and reuses it, which is what stops a lost BLE markSynced ACK creating a second take. ⚠️ **There is still no database unique constraint behind that probe.** Under a genuine race the probe can be passed twice. If you get two rows for one recording here, that is the known gap, not a new defect — log it against RQ-03. | V7: Count session records, storage objects, processing attempts, transcripts, and reports linked to the source recording. | W7: Repeated actions never create duplicate user-visible sessions, duplicate reports, or conflicting final states. | X7: Not Run | Z7: =COUNTIF('Defect Log'!$C$2:$C$500,$A7)
A8: SATE-REC-001 | B8: In scope | D8: Both | E8: Tester + Engineer | F8: Recorder · phone · browser + Supabase read access · Serial console on the recorder | G8: Recorder Interruption and Local Persistence | H8: Graceful recorder restart during an active recording | I8: P0 | J8: Recovery | K8: RQ-06, RQ-03, RQ-04 | L8: 3 | M8: RQ-06 | N8: SATE Recorder; Local Storage; Supabase | O8: Verify that a normal restart during recording does not silently lose captured audio. | P8: Recorder battery and storage are sufficient; a session is actively recording. | Q8: 5-minute intended recording; restart after approximately 2 minutes. | R8: 1. Start recording and speak a beginning marker. 2. After two minutes, perform a normal device restart. 3. Restart the recorder. 4. Inspect recovered/pending sessions. 5. Sync any recovered partial session. | S8: The recorder clearly identifies the interrupted session. Recommended behavior: preserve the recorded portion and label it Interrupted; do not silently discard it. | T8: At most one interrupted session is created for the captured audio. Any upload uses the original session identity or a clearly linked recovery identity. | U8: Segments flush to SD roughly every 5 s, so at most ~5 s of tail is at risk. On boot maybeResumeRecording() re-enters the same session — **every** take resumes, button-started and server-started alike (fw ≥1.5.16). Serial should show [CONN] resume … session N. The session number must not change: numbers are allocated monotonically and never renumbered (fw ≥1.5.20). A hole in the numbering is legal; a *reused* number is a defect. | V8: Play the recovered audio; verify beginning marker, duration, file readability, status, and absence of duplication. | W8: Captured audio is preserved or intentionally rejected according to a documented rule, and the user receives an explicit status. | X8: Not Run | Z8: =COUNTIF('Defect Log'!$C$2:$C$500,$A8)
A9: SATE-REC-002 | B9: In scope | D9: Both | E9: Tester + Engineer | F9: Recorder · phone · browser + Supabase read access · Serial console on the recorder | G9: Recorder Interruption and Local Persistence | H9: Forced power loss during an active recording | I9: P0 | J9: Recovery / Fault Injection | K9: RQ-04, RQ-06 | L9: 2 | M9: RQ-06 | N9: SATE Recorder; Local Storage | O9: Verify crash-safe local audio persistence when shutdown cannot complete cleanly. | P9: Recorder is actively recording; tester can disconnect power or force shutdown safely. | Q9: 5-minute intended recording; forced shutdown after approximately 2 minutes. | R9: 1. Start recording and speak a beginning marker. 2. Force power loss without using the normal stop control. 3. Restore power. 4. Inspect recovered data and device messages. 5. Sync any recoverable session. | S9: The recorder reports an interrupted or recovered session rather than showing a completed recording. It must not claim success if the audio is corrupted. | T9: Recovered audio is either stored as one valid partial session or quarantined as corrupted with a traceable error. No phantom Completed session is created. | U9: Same resume path as REC-001, and the one that matters most. Two things to check on the serial log: [MEM] ready (boot completed) and [CONN] resume … session N. The resume runs from loop(), never setup() (fw ≥1.5.17) — if the device comes back and is *unreachable* (no heartbeat, remote stop ignored), that regression is back and it is a release blocker: the take runs to the ~62-minute ceiling with nobody able to stop it. | V9: Verify file readability, duration, beginning marker, session count, error logs, and local cleanup behavior. | W9: No silent data loss, false Completed state, or duplicate session occurs. | X9: Not Run | Z9: =COUNTIF('Defect Log'!$C$2:$C$500,$A9)
A10: SATE-REC-003 | B10: In scope | D10: Both | E10: Tester + Engineer | F10: Recorder · phone · browser + Supabase read access · Serial console · bench power supply or drained cell | G10: Recorder Interruption and Local Persistence | H10: Low-battery shutdown during recording | I10: P0 | J10: Recovery / Hardware | K10: RQ-06, RQ-20 | L10: 2 | M10: RQ-06, RQ-20 | N10: SATE Recorder; Battery Management; Local Storage | O10: Verify low-battery warnings and safe session preservation. | P10: Recorder battery can be reduced to the low-battery threshold. | Q10: Recording continues until low-battery warning and shutdown. | R10: 1. Begin a recording with low remaining battery. 2. Continue until warning appears. 3. Observe whether recording stops automatically or the device shuts down. 4. Recharge and restart. 5. Inspect and sync the session. | S10: A warning appears early enough for action. Recommended behavior: safely stop and save before shutdown when possible. | T10: One valid partial or completed session is preserved with an accurate reason/status. No corrupted Completed session is created. | U10: Low-voltage cutoff uses the GPIO9 battery sense (analogReadMilliVolts × 2 behind the board's 0.5 divider). Confirm the partial take survived to SD and later uploads with its real byte count. Battery telemetry lands in sate_devices.battery_pct / battery_mv via the heartbeat. | V10: Check duration, file readability, battery-related event log, status, and upload result. | W10: Audio captured before shutdown is handled according to the documented low-battery rule with no false success. | X10: Not Run | Z10: =COUNTIF('Defect Log'!$C$2:$C$500,$A10)
A11: SATE-REC-004 | B11: In scope | D11: Both | E11: Tester + Engineer | F11: Recorder · phone · browser + Supabase read access | G11: Recorder Interruption and Local Persistence | H11: Insufficient local storage before recording starts | I11: P0 | J11: Negative / Boundary | K11: RQ-04, RQ-07 | L11: 2 | M11: RQ-07 | N11: SATE Recorder; Local Storage | O11: Verify that the recorder prevents a session that cannot be stored safely. | P11: Local storage is below the defined minimum free-space threshold. | Q11: Recorder with intentionally reduced free storage. | R11: 1. Attempt to start a recording. 2. Observe the message and controls. 3. Free sufficient storage. 4. Retry recording. | S11: The recorder blocks recording or clearly warns the user before capture begins. After space is freed, normal recording is available. | T11: No incomplete session or empty backend record is created from the blocked attempt. | U11: Nothing reaches the server. Confirm no orphan row in sate_device_sessions and no object in the device-sessions bucket. A row with storage_path set but no object is the failure signature to look for. | V11: Verify free-space check, absence of zero-byte files, absence of orphan session records, and successful retry after cleanup. | W11: The user cannot unknowingly begin a recording that the device cannot preserve. | X11: Not Run | Z11: =COUNTIF('Defect Log'!$C$2:$C$500,$A11)
A12: SATE-REC-005 | B12: In scope | D12: Both | E12: Tester + Engineer | F12: Recorder · phone · browser + Supabase read access · SD card able to be filled to capacity | G12: Recorder Interruption and Local Persistence | H12: Local storage becomes full during recording | I12: P0 | J12: Recovery / Boundary | K12: RQ-04, RQ-06 | L12: 2 | M12: RQ-06 | N12: SATE Recorder; Local Storage | O12: Verify safe termination when storage is exhausted during capture. | P12: Recorder starts with enough space for a short recording but not for the planned duration. | Q12: Continue recording until storage is exhausted. | R12: 1. Start recording. 2. Continue until the storage-full condition occurs. 3. Observe device behavior. 4. Restart if required. 5. Inspect and sync recoverable audio. | S12: The recorder stops safely and shows a specific storage error. It must not continue displaying Recording after writes have failed. | T12: Captured audio is finalized if possible, or marked corrupted/interrupted. No zero-byte Completed session is created. | U12: The recorder must stop cleanly and keep what it captured. Server-side the take arrives as a normal short session. Verify byte count matches sessionAssembledBytes() semantics: part0 keeps its 44-byte WAV header, later parts are stripped — the server's stored bytes must equal that exactly, because GET /sessions/verify compares it before the device frees audio. | V12: Check final playable duration, file size, error status, session count, and cleanup of temporary files. | W12: The condition is detected, communicated, and handled without silent corruption or false completion. | X12: Not Run | Z12: =COUNTIF('Defect Log'!$C$2:$C$500,$A12)
A13: SATE-REC-006 | B13: In scope | D13: Both | E13: Tester + Engineer | F13: Recorder · phone · browser + Supabase read access · Serial console · ability to cut power at a chosen moment | G13: Recorder Interruption and Local Persistence | H13: Restart during the local save/finalization step | I13: P0 | J13: Recovery | K13: RQ-03, RQ-04, RQ-06 | L13: 3 | M13: RQ-06 | N13: SATE Recorder; Local Storage; Upload Queue | O13: Verify crash safety while the recorder finalizes audio and creates the upload queue item. | P13: A recording is ready to stop; tester can restart immediately after Stop. | Q13: 5-minute recording. | R13: 1. Record five minutes. 2. Press Stop. 3. Restart the recorder while Save/Finalizing is displayed. 4. Restart and inspect session/queue state. 5. Allow synchronization. | S13: After restart, the session is either safely recovered and queued once or clearly marked failed. The UI must not show two copies. | T13: Only one final audio object/session is created. Temporary files are reconciled or removed. | U13: The crash window is inside finalization. Either a complete take or a recoverable partial is acceptable; a take marked synced with no server object is not. Check for the ghost signature: a .synced marker on device with no matching row/object server-side. | V13: Compare local files, queue entries, backend records, audio duration, and processing jobs. | W13: No duplicate session, orphan temporary file affecting storage, or silent loss occurs. | X13: Not Run | Z13: =COUNTIF('Defect Log'!$C$2:$C$500,$A13)
A14: SATE-REC-007 | B14: In scope | D14: Both | E14: Tester + Engineer | F14: Recorder · phone · browser + Supabase read access · Serial console on the recorder | G14: Recorder Interruption and Local Persistence | H14: Restart after recording stops but before upload begins | I14: P0 | J14: Recovery | K14: RQ-03, RQ-08, RQ-10 | L14: 3 | N14: SATE Recorder; Upload Queue; Supabase | O14: Verify persistence of a locally saved, not-yet-uploaded session. | P14: Recording has stopped and is locally saved; network upload has not begun. | Q14: 3-minute recording. | R14: 1. Record and stop the session. 2. Restart immediately before upload starts. 3. Reconnect to network. 4. Observe queue recovery and final result. | S14: The pending session reappears after restart and uploads automatically or through the documented resume action. | T14: One queue item maps to one session. Status progresses from pending to completed without creating a second session. | U14: Nothing has been uploaded yet, so the server should show no row until connectivity returns. Then exactly one row appears. This is the case that proves reclaim safety: the device must NOT free the audio until GET /api/sessions/verify (device-api ≥v15) returns stored:true — which checks the row **and** objectExists. Any doubt keeps the audio. | V14: Verify local-to-server session identity, queue persistence, audio completeness, and final status. | W14: The pending session survives restart and completes without user re-recording. | X14: Not Run | Z14: =COUNTIF('Defect Log'!$C$2:$C$500,$A14)
A15: SATE-NET-001 | B15: In scope | D15: Both | E15: Tester + Engineer | F15: Recorder · phone · browser + Supabase read access | G15: Network, Offline, and Upload Recovery | H15: Recording starts and ends while fully offline | I15: P0 | J15: Offline / Recovery | K15: RQ-04, RQ-08, RQ-10 | L15: 3 | N15: SATE Recorder; Local Storage; Upload Queue; Supabase | O15: Verify offline recording and automatic upload when connectivity returns. | P15: Wi-Fi is disabled or unavailable before the session starts. | Q15: 5-minute recording; restore Internet after the session is saved. | R15: 1. Disable connectivity. 2. Record and stop a session. 3. Confirm local Pending Upload status. 4. Restore Internet. 5. Wait without manually creating a second session. 6. Review the session on the Web App. | S15: Recording works offline. The session is visibly queued. When Internet returns, upload starts automatically or at the documented trigger. | T15: One queued session uploads once, processes, and reaches Completed. | U15: No server activity during the take. On reconnect, one row appears with the full byte count. Confirm the recorder did not free SD audio in the meantime — verified trim only releases audio for synced takes older than the newest KEEP_AUDIO_SESSIONS (=5) **and** only after byte-exact stored:true. | V15: Verify local persistence, same session ID before/after upload, complete audio, queue removal only after server acknowledgement, and no duplicate. | W15: Offline recording is preserved and completes automatically after connectivity returns. | X15: Not Run | Z15: =COUNTIF('Defect Log'!$C$2:$C$500,$A15)
A16: SATE-NET-002 | B16: In scope | D16: Both | E16: Tester + Engineer | F16: Recorder · phone · browser + Supabase read access | G16: Network, Offline, and Upload Recovery | H16: Internet connection is lost during recording | I16: P0 | J16: Offline / Functional | K16: RQ-04, RQ-10 | L16: 2 | N16: SATE Recorder; Local Storage; Network Detection | O16: Verify that recording is independent of Internet availability. | P16: Recording begins online. | Q16: 5-minute session; disable Internet after 1 minute and restore after Stop. | R16: 1. Start online recording. 2. Disable Internet during capture. 3. Continue recording. 4. Stop the session while offline. 5. Restore Internet and wait for completion. | S16: Recording continues without interruption. The device shows offline/pending status after Stop and later uploads normally. | T16: One complete audio object and one session are created after reconnection. | U16: The take continues locally; Wi-Fi loss must not stop capture. Watch for the upload retrying after association returns. If the device came up offline and the AP is down, the offline fallback still starts the net task so heartbeat, remote stop and OTA health-confirm keep working — verify the device is reachable during the take. | V16: Check audio for gaps at the disconnect point, duration, queue state, and final transcript match. | W16: No capture gap, crash, duplicate session, or misleading completion status occurs. | X16: Not Run | Z16: =COUNTIF('Defect Log'!$C$2:$C$500,$A16)
A17: SATE-NET-003 | B17: In scope | D17: Both | E17: Tester + Engineer | F17: Recorder · phone · browser + Supabase read access | G17: Network, Offline, and Upload Recovery | H17: Internet is lost after Stop but before upload starts | I17: P0 | J17: Recovery | K17: RQ-08, RQ-10 | L17: 2 | N17: SATE Recorder; Upload Queue | O17: Verify correct queuing when a saved session cannot begin uploading. | P17: Recording is complete; upload has not yet started. | Q17: 3-minute recording. | R17: 1. Stop the recording. 2. Immediately disable Internet. 3. Confirm Pending Upload status. 4. Restore Internet. 5. Observe automatic upload and processing. | S17: The session remains visible and queued. No repeated user action is required unless explicitly designed. | T17: The same session is uploaded once after reconnection. Queue state is cleared only after successful acknowledgement. | U17: Nothing on the server until connectivity returns, then one complete row. Check GET /sessions/upload-progress (device-api ≥v16) reports zero in-flight bytes while offline. | V17: Verify one session, one audio object, correct status transitions, and no loss of local file before acknowledgement. | W17: The saved session survives the outage and completes once connectivity returns. | X17: Not Run | Z17: =COUNTIF('Defect Log'!$C$2:$C$500,$A17)
A18: SATE-NET-004 | B18: In scope | C18: Run the recorder's direct Wi-Fi upload path. | D18: Both | E18: Tester + Engineer | F18: Recorder · phone · browser + Supabase read access | G18: Network, Offline, and Upload Recovery | H18: Internet drops during an active upload | I18: P0 | J18: Recovery / Data Integrity | K18: RQ-03, RQ-09, RQ-10 | L18: 3 | M18: RQ-09 | N18: SATE Recorder or Mobile App; Supabase Storage; Upload Queue | O18: Verify upload retry or resume without duplication or file corruption. | P18: An upload large enough to interrupt is in progress. | Q18: 10-minute or larger session; disable Internet at approximately 40% upload. | R18: 1. Start upload. 2. Disable Internet mid-transfer. 3. Wait for failure detection. 4. Restore Internet. 5. Allow automatic retry/resume. 6. Inspect backend and Web App. | S18: The session changes to a retryable/pending state and later completes. The UI does not remain permanently stuck at Uploading. | T18: Upload resumes or restarts according to the documented strategy. Incomplete objects are overwritten, completed, or cleaned safely. One final session exists. | U18: Chunked upload stores each slice as its own _tmp/<patient>/s<n>/<offset>.part object and stitches once on the final slice (device-api ≥v12 — the earlier design rewrote the whole temp blob per slice, was quadratic, and stalled long uploads). A resumed upload must not duplicate parts. If the sizes disagree the edge rejects rather than storing a corrupt WAV. Inspect leftover _tmp/ objects after success — they should be gone. | V18: Compare local/server file size, duration, checksum if available, beginning/end markers, object count, and processing job count. | W18: The final server audio is complete and playable, with exactly one user-visible session and no orphan file that affects later processing. | X18: Not Run | Z18: =COUNTIF('Defect Log'!$C$2:$C$500,$A18)
A19: SATE-NET-005 | B19: In scope (reduced) | C19: Recorder idle or asleep when connectivity returns. Skip phone background / screen-lock. | D19: Both | E19: Tester + Engineer | F19: Recorder · phone · browser + Supabase read access | G19: Network, Offline, and Upload Recovery | H19: Connectivity returns while app/device is in background or screen is locked | I19: P0 | J19: Recovery / Mobile Lifecycle | K19: RQ-10, RQ-19 | L19: 2 | N19: SATE Mobile App; SATE Recorder; OS Background Services; Upload Queue | O19: Verify the documented background upload behavior. | P19: A session is pending offline; mobile app is backgrounded or phone is locked before Internet returns. | Q19: Pending 5-minute session; supported phone OS. | R19: 1. Create an offline pending session. 2. Background the app or lock the phone. 3. Restore Internet. 4. Wait for the documented background window. 5. Unlock/open the app if necessary. 6. Check completion. | S19: Upload either starts in the background as designed or begins immediately when the app is reopened. The pending session is not lost. | T19: Queue state remains durable and the session uploads once. | U19: Server side just sees a later upload. The interesting check is that only ONE upload lands, not one per foreground/background transition. | V19: Verify OS logs if available, queue persistence, session count, and final audio completeness. | W19: Behavior matches the supported background policy and no session remains permanently stranded. | X19: Not Run | Z19: =COUNTIF('Defect Log'!$C$2:$C$500,$A19)
A20: SATE-NET-006 | B20: In scope (reduced) | C20: Recorder's own network detection only. Skip the app's detection. | D20: Both | E20: Tester + Engineer | F20: Recorder · phone · browser + Supabase read access | G20: Network, Offline, and Upload Recovery | H20: Wi-Fi is connected but Internet access is unavailable | I20: P1 | J20: Negative / Recovery | K20: RQ-10 | L20: 1 | N20: SATE Recorder; Mobile App; Network Detection | O20: Verify that the system checks real Internet/backend reachability rather than Wi-Fi association only. | P20: Connect to a router with no Internet access. | Q20: 3-minute session. | R20: 1. Connect to Wi-Fi without Internet. 2. Record and stop a session. 3. Observe upload status. 4. Restore Internet without changing Wi-Fi if possible. 5. Wait for upload. | S20: The UI indicates Offline, Cannot Reach Service, or Pending Upload rather than claiming successful upload. | T20: No false server acknowledgement is stored. The queue retries safely after reachability returns. | U20: Associated-but-no-internet must be classified as a transient failure, not a permanent one. The session should stay queued (or return to it), never jump to error. | V20: Verify local file remains, backend has no incomplete Completed record, and final upload creates one session. | W20: The system does not confuse Wi-Fi connection with successful synchronization. | X20: Not Run | Z20: =COUNTIF('Defect Log'!$C$2:$C$500,$A20)
A21: SATE-NET-007 | B21: In scope (reduced) | C21: Recorder behind the captive portal only. Skip the app. | D21: Both | E21: Tester + Engineer | F21: Recorder · phone · browser + Supabase read access · A captive-portal access point | G21: Network, Offline, and Upload Recovery | H21: Captive portal or authentication-required Wi-Fi | I21: P2 | J21: Negative / Compatibility | K21: RQ-10, RQ-19 | L21: 2 | N21: SATE Recorder; Mobile App; Network Detection | O21: Verify safe behavior on a network that requires browser sign-in. | P21: Connect to a captive-portal network without completing sign-in. | Q21: 3-minute pending session. | R21: 1. Connect to captive-portal Wi-Fi. 2. Attempt sync. 3. Complete portal sign-in. 4. Observe retry and completion. | S21: The system shows a network error/pending state until Internet is usable, then retries without creating a second session. | T21: No invalid Completed state or duplicate upload occurs. | U21: Captive portal returns an HTTP 200 with HTML rather than the expected JSON. Confirm the device treats an unparseable body as a failure and keeps the audio — a 2xx alone must never be read as "durably stored". This is exactly the class that produced the 413 ghosts. | V21: Verify queue durability, one final session, and correct error recovery. | W21: The session remains safe until the network becomes usable and then completes normally. | X21: Not Run | Z21: =COUNTIF('Defect Log'!$C$2:$C$500,$A21)
A22: SATE-NET-008 | B22: In scope | C22: Run the recorder's direct Wi-Fi upload path. | D22: Both | E22: Tester + Engineer | F22: Recorder · phone · browser + Supabase read access | G22: Network, Offline, and Upload Recovery | H22: Switch from one Wi-Fi network to another or to a hotspot during upload | I22: P1 | J22: Recovery / Compatibility | K22: RQ-09, RQ-10 | L22: 2 | M22: RQ-09 | N22: SATE Recorder or Mobile App; Upload Queue; Supabase | O22: Verify transfer recovery after IP/network changes. | P22: Upload is in progress and a second valid network is available. | Q22: 10-minute recording. | R22: 1. Start upload on Network A. 2. Disconnect from Network A mid-upload. 3. Connect to Network B or hotspot. 4. Wait for retry/resume. 5. Inspect final session. | S22: The upload recovers without requiring a new recording. Status updates remain understandable. | T22: One final audio object is committed. Any partial upload from Network A is reconciled. | U22: Same as NET-004: the stitch must be resilient to the connection changing underneath it. Check final bytes equals the device's assembled byte count. | V22: Check object/session counts, file completeness, processing job count, and final transcript. | W22: Network switching does not produce corruption, duplication, or permanent Uploading state. | X22: Not Run | Z22: =COUNTIF('Defect Log'!$C$2:$C$500,$A22)
A23: SATE-NET-009 | B23: In scope | C23: Run the recorder's direct Wi-Fi upload path. | D23: Both | E23: Tester + Engineer | F23: Recorder · phone · browser + Supabase read access | G23: Network, Offline, and Upload Recovery | H23: Rapidly flapping or weak network | I23: P1 | J23: Stress / Reliability | K23: RQ-09, RQ-10, RQ-20 | L23: 3 | M23: RQ-09, RQ-20 | N23: SATE Recorder or Mobile App; Upload Queue | O23: Verify bounded retry behavior under unstable connectivity. | P23: Network can be toggled or throttled. | Q23: 10-minute session; alternate online/offline several times. | R23: 1. Start upload. 2. Alternate online and offline states several times. 3. End with a stable connection. 4. Wait for completion. 5. Review retry count and final records. | S23: The UI does not spam duplicate sessions or become unresponsive. It eventually completes or reaches a clear retryable state. | T23: Retries are bounded and idempotent. One canonical session and one valid final audio object remain. | U23: Expect repeated attempts increments. requeue_session applies backoff for transient failures; the watchdog requeue_stale_sessions(p_stuck_minutes=45, p_max_attempts=3) reclaims anything abandoned. The session must not exceed MAX_ATTEMPTS (3) and must settle. | V23: Review attempt count, backoff timing, session/object counts, final file integrity, and queue cleanup. | W23: The system recovers when stability returns and never creates conflicting final states. | X23: Not Run | Z23: =COUNTIF('Defect Log'!$C$2:$C$500,$A23)
A24: SATE-NET-010 | B24: In scope | C24: Use the recorder's retry, or the web app's Retry control. | D24: Both | E24: Tester + Engineer | F24: Recorder · phone · browser + Supabase read access | G24: Network, Offline, and Upload Recovery | H24: User taps manual Retry while automatic retry is already running | I24: P0 | J24: Concurrency / Idempotency | K24: RQ-03, RQ-09, RQ-13 | L24: 3 | M24: RQ-09, RQ-13 | N24: SATE Mobile App or Recorder; Upload Queue; Supabase | O24: Verify that manual and automatic retry paths cannot duplicate the upload. | P24: A retryable upload failure is present and automatic retry is scheduled or active. | Q24: 5-minute failed/pending session. | R24: 1. Trigger an upload failure. 2. Restore connectivity. 3. Tap Retry repeatedly while automatic retry begins. 4. Wait for final completion. 5. Inspect backend attempts and records. | S24: Only one active upload is presented to the user. Extra taps are disabled, ignored, or safely deduplicated. | T24: Multiple requests, if sent, resolve to one canonical session/object and one final processing result. | U24: Concurrent retry prevention. The user Retry route is POST /sessions/:id/retry (device-api ≥v14) and it **only accepts a session in error** — a processing row is refused, which is what stops a manual tap racing the container. claim_next_session is SELECT … FOR UPDATE SKIP LOCKED, so a double claim is impossible even if two workers ran. Confirm attempts increments by one, not two. | V24: Count upload requests, storage objects, sessions, processing jobs, and user-visible entries. | W24: Manual/automatic retry concurrency never creates a duplicate or corrupt final session. | X24: Not Run | Z24: =COUNTIF('Defect Log'!$C$2:$C$500,$A24)
A25: SATE-QUE-001 | B25: In scope | D25: Both | E25: Tester + Engineer | F25: Recorder · phone · browser + Supabase read access | G25: Queue, Batch, and Concurrency | H25: Five recordings made consecutively while online | I25: P0 | J25: Functional / Batch | K25: RQ-03, RQ-08 | L25: 2 | N25: SATE Recorder; Upload Queue; Supabase; AI service | O25: Verify unique session creation and correct ordering for normal back-to-back use. | P25: Stable network; no pending sessions. | Q25: Recordings of 30 sec, 1 min, 2 min, 3 min, and 5 min, each with a unique spoken label. | R25: 1. Create five recordings with less than 20 seconds between sessions. 2. Allow uploads to occur. 3. Review the queue and Web App. 4. Open each transcript. | S25: All five sessions appear once with correct order, labels, dates, and durations. Starting the next session does not overwrite the previous one. | T25: Five unique session IDs, five correct audio objects, and five result sets are created. | U25: Five rows, five distinct session_numbers, five recordings. The container drains the queue **serially** (max_instances = 1, GPU concurrency is 1 anyway), so expect sequential completion, not parallel. Total time ≈ sum of individual processing times — that is by design, not a stall. | V25: Match each audio beginning/end marker to its transcript; compare timestamps, duration, and session IDs. | W25: All five sessions complete without overwrite, merging, omission, or cross-session transcript assignment. | X25: Not Run | Z25: =COUNTIF('Defect Log'!$C$2:$C$500,$A25)
A26: SATE-QUE-002 | B26: In scope | D26: Both | E26: Tester + Engineer | F26: Recorder · phone · browser + Supabase read access | G26: Queue, Batch, and Concurrency | H26: Start a new recording while the previous session is uploading | I26: P0 | J26: Concurrency / Functional | K26: RQ-03, RQ-08, RQ-10 | L26: 3 | N26: SATE Recorder; Upload Queue; Local Storage; Supabase | O26: Verify simultaneous recording and background upload, or correct prevention if unsupported. | P26: Session A is uploading; recorder is ready for another action. | Q26: Session A: 10 minutes; Session B: 2 minutes. | R26: 1. Start uploading Session A. 2. Attempt to start Session B. 3. Complete Session B. 4. Wait for both sessions to finish. 5. Review results. | S26: The UI follows the documented rule: either allows Session B safely or clearly blocks it. If allowed, statuses remain distinct. | T26: Sessions A and B retain unique IDs, files, statuses, and processing jobs. | U26: A new take must not disturb an in-flight upload. Note the delete/upload interaction rule: a delete defers-and-drops the uploader **only if it is latched on that exact session** (upDropReq); any other session's upload is untouched. | V26: Verify no audio mixing, file overwrite, shared session ID, or status crossover. | W26: Both sessions are handled correctly according to the documented concurrency requirement. | X26: Not Run | Z26: =COUNTIF('Defect Log'!$C$2:$C$500,$A26)
A27: SATE-QUE-003 | B27: In scope | D27: Both | E27: Tester + Engineer | F27: Recorder · phone · browser + Supabase read access | G27: Queue, Batch, and Concurrency | H27: Five offline recordings queued and uploaded later | I27: P0 | J27: Offline / Batch | K27: RQ-04, RQ-08, RQ-10 | L27: 3 | N27: SATE Recorder; Local Storage; Upload Queue; Supabase | O27: Verify durable multi-session queueing. | P27: Device is offline and has sufficient storage. | Q27: Five recordings with unique labels and varying lengths. | R27: 1. Disable Internet. 2. Record five sessions. 3. Restart the recorder/app once while still offline. 4. Confirm all five remain queued. 5. Restore Internet. 6. Wait for all sessions to complete. | S27: All five queued sessions remain visible after restart and later upload. Progress/status is shown per session. | T27: Five unique sessions and five complete audio objects are committed. Queue entries are removed only after acknowledgement. | U27: Five queued rows appear on reconnect. Order is by created_at; the claim query is status='queued' order by created_at. Session numbers must be distinct and none reused. | V27: Check queue persistence, upload order, session count, audio/transcript mapping, and no duplicates. | W27: No queued session is lost, merged, duplicated, or indefinitely blocked. | X27: Not Run | Z27: =COUNTIF('Defect Log'!$C$2:$C$500,$A27)
A28: SATE-QUE-004 | B28: In scope | D28: Both | E28: Tester + Engineer | F28: Recorder · phone · browser + Supabase read access | G28: Queue, Batch, and Concurrency | H28: One queued session fails while later sessions continue | I28: P0 | J28: Reliability / Fault Isolation | K28: RQ-08, RQ-11, RQ-13 | L28: 3 | M28: RQ-11, RQ-13 | N28: Upload Queue; Supabase; AI service | O28: Verify that a single bad item does not block the entire queue. | P28: At least three sessions are queued; a fault can be injected for Session 2. | Q28: Three queued sessions; cause Session 2 upload or processing to fail. | R28: 1. Queue Sessions 1-3. 2. Inject a failure for Session 2. 3. Restore normal service. 4. Observe Sessions 1 and 3. 5. Retry Session 2. | S28: Each session shows its own status. Failure of Session 2 does not hide or freeze Sessions 1 and 3. | T28: Sessions 1 and 3 reach Completed. Session 2 reaches a defined failed/retryable state and can later complete without duplication. | U28: Per-item fault isolation. One row going to error must not block the others — verify the remaining four reach done. pg_cron pings the Worker /tick every minute to keep the container warm; if everything stalls together, check the container is awake before blaming the queue. | V28: Verify per-session attempt counts, queue progression, final session count, and audio mapping. | W28: Queue processing is fault-isolated and recoverable. | X28: Not Run | Z28: =COUNTIF('Defect Log'!$C$2:$C$500,$A28)
